Traceback (most recent call last):
  File "/Users/saskiad/opt/anaconda3/lib/python3.9/site-packages/jupyter_cache/executors/utils.py", line 51, in single_nb_execution
    executenb(
  File "/Users/saskiad/opt/anaconda3/lib/python3.9/site-packages/nbclient/client.py", line 1204, in execute
    return NotebookClient(nb=nb, resources=resources, km=km, **kwargs).execute()
  File "/Users/saskiad/opt/anaconda3/lib/python3.9/site-packages/nbclient/util.py", line 84, in wrapped
    return just_run(coro(*args, **kwargs))
  File "/Users/saskiad/opt/anaconda3/lib/python3.9/site-packages/nbclient/util.py", line 62, in just_run
    return loop.run_until_complete(coro)
  File "/Users/saskiad/opt/anaconda3/lib/python3.9/asyncio/base_events.py", line 647, in run_until_complete
    return future.result()
  File "/Users/saskiad/opt/anaconda3/lib/python3.9/site-packages/nbclient/client.py", line 663, in async_execute
    await self.async_execute_cell(
  File "/Users/saskiad/opt/anaconda3/lib/python3.9/site-packages/nbclient/client.py", line 965, in async_execute_cell
    await self._check_raise_for_error(cell, cell_index, exec_reply)
  File "/Users/saskiad/opt/anaconda3/lib/python3.9/site-packages/nbclient/client.py", line 862, in _check_raise_for_error
    raise CellExecutionError.from_cell_and_msg(cell, exec_reply_content)
nbclient.exceptions.CellExecutionError: An error occurred while executing the following cell:
------------------
fig = plt.figure(figsize=(12,5))
ax1 = plt.subplot(131)
ax1.imshow(rois_a[index_a,:,:])
ax2 = plt.subplot(132)
ax2.imshow(rois_a[index_b,:,:])
ax3 = plt.subplot(133)
ax3.imshow(rois_a[index_c,:,:])
------------------

[0;31m---------------------------------------------------------------------------[0m
[0;31mTypeError[0m                                 Traceback (most recent call last)
[0;32m/var/folders/qh/5lyvn7d93mzft9kchq7xsqkw0000gp/T/ipykernel_73981/2633090789.py[0m in [0;36m<module>[0;34m[0m
[1;32m      1[0m [0mfig[0m [0;34m=[0m [0mplt[0m[0;34m.[0m[0mfigure[0m[0;34m([0m[0mfigsize[0m[0;34m=[0m[0;34m([0m[0;36m12[0m[0;34m,[0m[0;36m5[0m[0;34m)[0m[0;34m)[0m[0;34m[0m[0;34m[0m[0m
[1;32m      2[0m [0max1[0m [0;34m=[0m [0mplt[0m[0;34m.[0m[0msubplot[0m[0;34m([0m[0;36m131[0m[0;34m)[0m[0;34m[0m[0;34m[0m[0m
[0;32m----> 3[0;31m [0max1[0m[0;34m.[0m[0mimshow[0m[0;34m([0m[0mrois_a[0m[0;34m[[0m[0mindex_a[0m[0;34m,[0m[0;34m:[0m[0;34m,[0m[0;34m:[0m[0;34m][0m[0;34m)[0m[0;34m[0m[0;34m[0m[0m
[0m[1;32m      4[0m [0max2[0m [0;34m=[0m [0mplt[0m[0;34m.[0m[0msubplot[0m[0;34m([0m[0;36m132[0m[0;34m)[0m[0;34m[0m[0;34m[0m[0m
[1;32m      5[0m [0max2[0m[0;34m.[0m[0mimshow[0m[0;34m([0m[0mrois_a[0m[0;34m[[0m[0mindex_b[0m[0;34m,[0m[0;34m:[0m[0;34m,[0m[0;34m:[0m[0;34m][0m[0;34m)[0m[0;34m[0m[0;34m[0m[0m

[0;32m~/opt/anaconda3/lib/python3.9/site-packages/matplotlib/__init__.py[0m in [0;36minner[0;34m(ax, data, *args, **kwargs)[0m
[1;32m   1359[0m     [0;32mdef[0m [0minner[0m[0;34m([0m[0max[0m[0;34m,[0m [0;34m*[0m[0margs[0m[0;34m,[0m [0mdata[0m[0;34m=[0m[0;32mNone[0m[0;34m,[0m [0;34m**[0m[0mkwargs[0m[0;34m)[0m[0;34m:[0m[0;34m[0m[0;34m[0m[0m
[1;32m   1360[0m         [0;32mif[0m [0mdata[0m [0;32mis[0m [0;32mNone[0m[0;34m:[0m[0;34m[0m[0;34m[0m[0m
[0;32m-> 1361[0;31m             [0;32mreturn[0m [0mfunc[0m[0;34m([0m[0max[0m[0;34m,[0m [0;34m*[0m[0mmap[0m[0;34m([0m[0msanitize_sequence[0m[0;34m,[0m [0margs[0m[0;34m)[0m[0;34m,[0m [0;34m**[0m[0mkwargs[0m[0;34m)[0m[0;34m[0m[0;34m[0m[0m
[0m[1;32m   1362[0m [0;34m[0m[0m
[1;32m   1363[0m         [0mbound[0m [0;34m=[0m [0mnew_sig[0m[0;34m.[0m[0mbind[0m[0;34m([0m[0max[0m[0;34m,[0m [0;34m*[0m[0margs[0m[0;34m,[0m [0;34m**[0m[0mkwargs[0m[0;34m)[0m[0;34m[0m[0;34m[0m[0m

[0;32m~/opt/anaconda3/lib/python3.9/site-packages/matplotlib/axes/_axes.py[0m in [0;36mimshow[0;34m(self, X, cmap, norm, aspect, interpolation, alpha, vmin, vmax, origin, extent, filternorm, filterrad, resample, url, **kwargs)[0m
[1;32m   5607[0m                               resample=resample, **kwargs)
[1;32m   5608[0m [0;34m[0m[0m
[0;32m-> 5609[0;31m         [0mim[0m[0;34m.[0m[0mset_data[0m[0;34m([0m[0mX[0m[0;34m)[0m[0;34m[0m[0;34m[0m[0m
[0m[1;32m   5610[0m         [0mim[0m[0;34m.[0m[0mset_alpha[0m[0;34m([0m[0malpha[0m[0;34m)[0m[0;34m[0m[0;34m[0m[0m
[1;32m   5611[0m         [0;32mif[0m [0mim[0m[0;34m.[0m[0mget_clip_path[0m[0;34m([0m[0;34m)[0m [0;32mis[0m [0;32mNone[0m[0;34m:[0m[0;34m[0m[0;34m[0m[0m

[0;32m~/opt/anaconda3/lib/python3.9/site-packages/matplotlib/image.py[0m in [0;36mset_data[0;34m(self, A)[0m
[1;32m    707[0m         if not (self._A.ndim == 2
[1;32m    708[0m                 or self._A.ndim == 3 and self._A.shape[-1] in [3, 4]):
[0;32m--> 709[0;31m             raise TypeError("Invalid shape {} for image data"
[0m[1;32m    710[0m                             .format(self._A.shape))
[1;32m    711[0m [0;34m[0m[0m

[0;31mTypeError[0m: Invalid shape (1, 512, 512) for image data
TypeError: Invalid shape (1, 512, 512) for image data

